Workbook

Sheet Sheet1
S3: Wir werden aus dem SAP feld Special stock und stock quality eins machen und das Ergebnis in das Feld Stock qual. Einfügen und entsprechende Gründe im KSOFT hinterlegen | AO3: Muss noch geprüft werden
A4: Nicht nach KSOFT | B4: Storearea | C4: Stock | D4: Nicht nach KSOFT | E4: Store Place | F4: Palett type | G4: Nicht nach KSOFT | H4: Customer Part number | I4: Description 1 | J4: Width | K4: TU | L4: TU2 | M4: Tambour | N4: m2 | O4: rm | P4: Weight/Quantity/gross weight | Q4: Nicht nach KSOFT | R4: Locked | S4: Locking reason | T4: Number of roll breaks | U4: I_FSC_PEFC | V4: I_FSC_PEFC | W4: Source | X4: Sorce pos. | Y4: Grammage | Z4: Core diameter | AA4: Internal Refernce | AB4: Remark altes Feld | AC4: siehe Spalte AN | AD4: Creation date | AE4: Nicht nach KSOFT | AF4: Nicht nach KSOFT | AG4: Nicht nach KSOFT | AH4: Nicht nach KSOFT | AI4: Nicht nach KSOFT | AJ4: Nicht nach KSOFT | AK4: Nicht nach KSOFT | AL4: Nicht nach KSOFT | AM4: Store in date | AN4: Matchcode Supplier | AO4: Price | AQ4: Remark (new field)
A5: Manufacturing costs | B5: Storage | C5: Stock number | D5: LA-Typ | E5: Storage | F5: LE-Typ | G5: Storage Section | H5: Material number | I5: Material description | J5: Manufacturing width CH | K5: HU-Nummer | L5: Supplier HU | M5: HU-nr tambour | N5: Sqare meter | O5: Length HU | P5: Gross weight | Q5: Special stock | R5: Blockage mark | S5: Stock qual. | T5: Joins | U5: FSC/PEFC | V5: Bez FSC/PEFC | W5: Purchase document | X5: Purchase doc. position | Y5: grammage | Z5: Core diameter | AA5: Comment + ZQM | AB5: Remark quality | AC5: Supplier | AD5: Lieferdatum Bestellung (GW) | AE5: Mütek CD | AF5: Mütek MD | AG5: Mütek value | AH5: Net price | AI5: Reservation order | AJ5: Production order | AK5: Lieferantenlos | AL5: Batch | AM5: Creation date | AN5: Matchcode Supplier | AO5: Net Price per 1 KG | AP5: Storage Periode | AQ5: Comment distribution | AR5: decor number
A6: 102.16 | B6: 1000 | C6: 111 | D6: 111 | E6: 520000 | F6: RO | G6: 001 | H6: 1006874 | I6: PBM 02 7904 070 | J6: 1290 | K6: 80376828 | L6: 40694321 | M6: 114820/20 | N6: 12126 | O6: 9400 | P6: 823 | U6: 03 | V6: FSC Mix Credit | W6: 4500153021 | X6: 20 | Y6: 70 | Z6: 76 | AC6: 501338 | AE6: 0 | AF6: 0 | AG6: 0 | AH6: 243 | AK6: 4500153021Gebr | AL6: 9000173492 | AM6: 44746 | AN6: =VLOOKUP(AC6,Tabelle1!A:B,2,FALSE) -> HOFF01 | AO6: =VLOOKUP(CONCATENATE(W6,X6),Tabelle2!A:E,5,FALSE) -> 11.463771 | AP6: 221
A7: 86.71 | B7: 1000 | C7: 111 | D7: 111 | E7: 510600 | F7: RO | G7: 001 | H7: 1391115 | I7: PBM 05 0380 070 P | J7: 1350 | K7: 10155996 | L7: 3200008010 | M7: 61193489-001 | N7: 9180 | O7: 6800 | P7: 648 | U7: 03 | V7: FSC Mix Credit | W7: 4500125652 | X7: 10 | Y7: 70 | Z7: 76 | AC7: 501340 | AD7: 43810 | AE7: 0 | AF7: 0 | AG7: 0 | AH7: 1.66 | AK7: 4500125652Papi | AL7: 9000152864 | AM7: 44070 | AN7: =VLOOKUP(AC7,Tabelle1!A:B,2,FALSE) -> KÖHL01 | AO7: =VLOOKUP(CONCATENATE(W7,X7),Tabelle2!A:E,5,FALSE) -> 7.3093125 | AP7: 897
A8: 86.71 | B8: 1000 | C8: 111 | D8: 111 | E8: 511200 | F8: RO | G8: 001 | H8: 1391115 | I8: PBM 05 0380 070 P | J8: 1420 | K8: 80383824 | L8: 40705607 | M8: 115092 | N8: 2939.4 | O8: 2070 | P8: 205.76 | U8: 03 | V8: FSC Mix Credit | W8: 4500154765 | X8: 30 | Y8: 70 | Z8: 76 | AC8: 501338 | AE8: 0 | AF8: 0 | AG8: 0 | AH8: 276 | AI8: 1183326 | AK8: 4500154765Gebr | AL8: 9000132932 | AM8: 44872 | AN8: =VLOOKUP(AC8,Tabelle1!A:B,2,FALSE) -> HOFF01 | AO8: =VLOOKUP(CONCATENATE(W8,X8),Tabelle2!A:E,5,FALSE) -> 12.943848 | AP8: 95
A9: 86.71 | B9: 1000 | C9: 111 | D9: 111 | E9: 510700 | F9: RO | G9: 001 | H9: 1391115 | I9: PBM 05 0380 070 P | J9: 1840 | K9: 80378827 | L9: 40699243 | M9: 114952 | N9: 9972.8 | O9: 5420 | P9: 698.1 | U9: 03 | V9: FSC Mix Credit | W9: 4500153741 | X9: 10 | Y9: 70 | Z9: 76 | AC9: 501338 | AE9: 0 | AF9: 0 | AG9: 0 | AH9: 249 | AK9: 4500153741Gebr | AL9: 9000116352 | AM9: 44795 | AN9: =VLOOKUP(AC9,Tabelle1!A:B,2,FALSE) -> HOFF01 | AO9: =VLOOKUP(CONCATENATE(W9,X9),Tabelle2!A:E,5,FALSE) -> 11.822519 | AP9: 172
A10: 86.71 | B10: 1000 | C10: 111 | D10: 111 | E10: 511000 | F10: RO | G10: 001 | H10: 1391115 | I10: PBM 05 0380 070 P | J10: 2070 | K10: 80383817 | L10: 40705485 | M10: 115092 | N10: 11385 | O10: 5500 | P10: 796.95 | U10: 03 | V10: FSC Mix Credit | W10: 4500154765 | X10: 20 | Y10: 70 | Z10: 76 | AC10: 501338 | AE10: 0 | AF10: 0 | AG10: 0 | AH10: 276 | AK10: 4500154765Gebr | AL10: 9000112988 | AM10: 44872 | AN10: =VLOOKUP(AC10,Tabelle1!A:B,2,FALSE) -> HOFF01 | AO10: =VLOOKUP(CONCATENATE(W10,X10),Tabelle2!A:E,5,FALSE) -> 12.943847 | AP10: 95
A11: 85.15 | B11: 1000 | C11: 111 | D11: 111 | E11: 020600 | F11: RO | G11: 001 | H11: 2010899 | I11: PBM 05 0483 070 | J11: 2100 | K11: 80386540 | L11: 40708874 | M11: 115207 | N11: 17073 | O11: 8130 | P11: 1164 | U11: 03 | V11: FSC Mix Credit | W11: 4500155354 | X11: 10 | Y11: 70 | Z11: 76 | AC11: 501338 | AE11: 0 | AF11: 0 | AG11: 0 | AH11: 259 | AK11: 4500155354Gebr | AL11: 9000518677 | AM11: 44907 | AN11: =VLOOKUP(AC11,Tabelle1!A:B,2,FALSE) -> HOFF01 | AO11: =VLOOKUP(CONCATENATE(W11,X11),Tabelle2!A:E,5,FALSE) -> 12.126639 | AP11: 60
A12: 85.15 | B12: 1000 | C12: 111 | D12: 111 | E12: 512800 | F12: RO | G12: 001 | H12: 2010899 | I12: PBM 05 0483 070 | J12: 2100 | K12: 80386541 | L12: 40708879 | M12: 115207 | N12: 13020 | O12: 6200 | P12: 884 | T12: 1 | U12: 03 | V12: FSC Mix Credit | W12: 4500155354 | X12: 10 | Y12: 70 | Z12: 76 | AC12: 501338 | AE12: 0 | AF12: 0 | AG12: 0 | AH12: 259 | AK12: 4500155354Gebr | AL12: 9000518677 | AM12: 44907 | AN12: =VLOOKUP(AC12,Tabelle1!A:B,2,FALSE) -> HOFF01 | AO12: =VLOOKUP(CONCATENATE(W12,X12),Tabelle2!A:E,5,FALSE) -> 12.126639 | AP12: 60
A13: 85.15 | B13: 1000 | C13: 111 | D13: 111 | E13: 512800 | F13: RO | G13: 001 | H13: 2010899 | I13: PBM 05 0483 070 | J13: 2100 | K13: 80386542 | L13: 40708881 | M13: 115207 | N13: 13125 | O13: 6250 | P13: 895 | U13: 03 | V13: FSC Mix Credit | W13: 4500155354 | X13: 10 | Y13: 70 | Z13: 76 | AC13: 501338 | AE13: 0 | AF13: 0 | AG13: 0 | AH13: 259 | AK13: 4500155354Gebr | AL13: 9000518677 | AM13: 44907 | AN13: =VLOOKUP(AC13,Tabelle1!A:B,2,FALSE) -> HOFF01 | AO13: =VLOOKUP(CONCATENATE(W13,X13),Tabelle2!A:E,5,FALSE) -> 12.126639 | AP13: 60
A14: 85.15 | B14: 1000 | C14: 111 | D14: 111 | E14: 020500 | F14: RO | G14: 001 | H14: 2010899 | I14: PBM 05 0483 070 | J14: 2100 | K14: 80386539 | L14: 40708872 | M14: 115207 | N14: 17010 | O14: 8100 | P14: 1160 | T14: 1 | U14: 03 | V14: FSC Mix Credit | W14: 4500155354 | X14: 10 | Y14: 70 | Z14: 76 | AC14: 501338 | AE14: 0 | AF14: 0 | AG14: 0 | AH14: 259 | AK14: 4500155354Gebr | AL14: 9000518677 | AM14: 44907 | AN14: =VLOOKUP(AC14,Tabelle1!A:B,2,FALSE) -> HOFF01 | AO14: =VLOOKUP(CONCATENATE(W14,X14),Tabelle2!A:E,5,FALSE) -> 12.126639 | AP14: 60
A15: 85.15 | B15: 1000 | C15: 111 | D15: 111 | E15: 020600 | F15: RO | G15: 001 | H15: 2010899 | I15: PBM 05 0483 070 | J15: 2100 | K15: 80386538 | L15: 40708866 | M15: 115207 | N15: 17010 | O15: 8100 | P15: 1163 | U15: 03 | V15: FSC Mix Credit | W15: 4500155354 | X15: 10 | Y15: 70 | Z15: 76 | AC15: 501338 | AE15: 0 | AF15: 0 | AG15: 0 | AH15: 259 | AK15: 4500155354Gebr | AL15: 9000518677 | AM15: 44907 | AN15: =VLOOKUP(AC15,Tabelle1!A:B,2,FALSE) -> HOFF01 | AO15: =VLOOKUP(CONCATENATE(W15,X15),Tabelle2!A:E,5,FALSE) -> 12.126639 | AP15: 60
A16: 93.22 | B16: 1000 | C16: 111 | D16: 101 | E16: NUR03 | F16: RO | G16: 001 | H16: 2023655 | I16: PIP 03 9299 057 TEC | J16: 626 | K16: 51973937 | L16: 2380024104 | N16: 2504 | O16: 4000 | P16: 142.73 | T16: 0 | U16: 03 | V16: FSC Mix Credit | X16: 0 | Y16: 57 | Z16: 76 | AE16: 0 | AF16: 0 | AG16: 0 | AH16: 0 | AJ16: 1300 | AK16: 4500155481Scho | AL16: 9000522349 | AM16: 44957 | AN16: =VLOOKUP(AC16,Tabelle1!A:B,2,FALSE) -> #N/A | AO16: =VLOOKUP(CONCATENATE(W16,X16),Tabelle2!A:E,5,FALSE) -> #N/A | AP16: 11
A17: 93.22 | B17: 1000 | C17: 111 | D17: 101 | E17: VAD01 | F17: RO | G17: 001 | H17: 2023655 | I17: PIP 03 9299 057 TEC | J17: 626 | K17: 51973936 | L17: 2380024104 | N17: 1815.4 | O17: 2900 | P17: 103.48 | T17: 0 | U17: 03 | V17: FSC Mix Credit | X17: 0 | Y17: 57 | Z17: 76 | AE17: 0 | AF17: 0 | AG17: 0 | AH17: 0 | AJ17: 1300 | AK17: 4500155481Scho | AL17: 9000522349 | AM17: 44957 | AN17: =VLOOKUP(AC17,Tabelle1!A:B,2,FALSE) -> #N/A | AO17: =VLOOKUP(CONCATENATE(W17,X17),Tabelle2!A:E,5,FALSE) -> #N/A | AP17: 11
A18: 99.96 | B18: 1000 | C18: 111 | D18: 111 | E18: 512600 | F18: RO | G18: 001 | H18: 2057501 | I18: PIP 01 9370 070 MUN | J18: 2560 | K18: 14322223 | L18: 615300056005 | M18: 400722 | N18: 20736 | O18: 8100 | P18: 1432 | T18: 1 | U18: 03 | V18: FSC Mix Credit | W18: 4500155925 | X18: 110 | Y18: 70 | Z18: 76 | AC18: 501337 | AE18: 0 | AF18: 0 | AG18: 0 | AH18: 303 | AK18: 4500155925Munk | AL18: 9000331179 | AM18: 44963 | AN18: =VLOOKUP(AC18,Tabelle1!A:B,2,FALSE) -> MUNK01 | AO18: =VLOOKUP(CONCATENATE(W18,X18),Tabelle2!A:E,5,FALSE) -> 14.280601 | AP18: 4
A19: 99.96 | B19: 1000 | C19: 111 | D19: 111 | E19: 512600 | F19: RO | G19: 001 | H19: 2057501 | I19: PIP 01 9370 070 MUN | J19: 2560 | K19: 14322219 | L19: 615300056001 | M19: 400722 | N19: 20736 | O19: 8100 | P19: 1431 | U19: 03 | V19: FSC Mix Credit | W19: 4500155925 | X19: 110 | Y19: 70 | Z19: 76 | AC19: 501337 | AE19: 0 | AF19: 0 | AG19: 0 | AH19: 303 | AK19: 4500155925Munk | AL19: 9000331179 | AM19: 44963 | AN19: =VLOOKUP(AC19,Tabelle1!A:B,2,FALSE) -> MUNK01 | AO19: =VLOOKUP(CONCATENATE(W19,X19),Tabelle2!A:E,5,FALSE) -> 14.280601 | AP19: 4
A20: 99.96 | B20: 1000 | C20: 111 | D20: 111 | E20: 511300 | F20: RO | G20: 001 | H20: 2057501 | I20: PIP 01 9370 070 MUN | J20: 2560 | K20: 80389086 | L20: 7192710004 | M20: 2057501 | N20: 9728 | O20: 3800 | P20: 680.96 | Q20: EV | R20: X | S20: S | U20: 03 | V20: FSC Mix Credit | W20: 4500155925 | X20: 110 | Y20: 70 | Z20: 76 | AB20: Kontrola jakości | AC20: 501337 | AE20: 0 | AF20: 0 | AG20: 0 | AH20: 303 | AK20: 4500155925Munk | AL20: 9000331179 | AM20: 44952 | AN20: =VLOOKUP(AC20,Tabelle1!A:B,2,FALSE) -> MUNK01 | AO20: =VLOOKUP(CONCATENATE(W20,X20),Tabelle2!A:E,5,FALSE) -> 14.280601 | AP20: 15
A21: 99.96 | B21: 1000 | C21: 111 | D21: 111 | E21: 511200 | F21: RO | G21: 001 | H21: 2057501 | I21: PIP 01 9370 070 MUN | J21: 2560 | K21: 80389085 | L21: 7192710003 | M21: 2057501 | N21: 20736 | O21: 8100 | P21: 1424 | Q21: EV | R21: X | S21: S | U21: 03 | V21: FSC Mix Credit | W21: 4500155925 | X21: 110 | Y21: 70 | Z21: 76 | AB21: Kontrola jakości | AC21: 501337 | AE21: 0 | AF21: 0 | AG21: 0 | AH21: 303 | AK21: 4500155925Munk | AL21: 9000331179 | AM21: 44952 | AN21: =VLOOKUP(AC21,Tabelle1!A:B,2,FALSE) -> MUNK01 | AO21: =VLOOKUP(CONCATENATE(W21,X21),Tabelle2!A:E,5,FALSE) -> 14.280601 | AP21: 15

Sheet Tabelle1
A1: FiBu Konto | B1: Matchcode | C1: Name 1
A2: 505466 | B2: AA 01 | C2: A&A Adam mierzejewski Mat. Poligraf
A3: 511459 | B3: ABAK01 | C3: ABAKOSTEEL S.C.
A4: 505870 | B4: ABAS01 | C4: ABASTO Bartłomiej Kieruzal
A5: 510278 | B5: ABB 01 | C5: ABB SP. Z O.O.
A6: 509455 | B6: ABBE01 | C6: ABBEYS Europejskie Doradztwo Finans
A7: 511663 | B7: ABBP01 | C7: ABB Power Grids Poland sp. z o.o.
A8: 507122 | B8: ABC 01 | C8: ABC Uslugi Transportowo-Handlowe
A9: 507299 | B9: ABCA01 | C9: ABCAD
A10: 511862 | B10: ABCE01 | C10: abc-eko GRZEGORZ WIECZOREK
A11: 504444 | B11: ABCK01 | C11: ABC kuchni PL Sp. z o.o. Sp. k.
A12: 510719 | B12: ABCR01 | C12: ABC Rental Wypożyczalnia Maszyn
A13: 512707 | B13: ABCV01 | C13: ABC VISION - SYSTEMY ZABEZPIECZEŃ
... A246: 510403 | B246: AUDI03 | C246: AUDIOTEKA SPÓŁKA AKCYJNA
A247: 501239 | B247: 37104 | C247: August Mink KG
A248: 502690 | B248: 37469 | C248: * August Mink KG
A249: 506885 | B249: AURA01 | C249: AURALIGHT POLSKA Sp. z o.o.
A250: 504674 | B250: AUTO01 | C250: AUTO MOTO EŁk Sp. z o.o.
A251: 507244 | B251: AUTO02 | C251: Autosoft
A252: 505638 | B252: AUTO03 | C252: AUTO-MOTO Halina Misiewicz
A253: 506632 | B253: AUTO04 | C253: AUTO LAND POLSKA SA
A254: 505336 | B254: AUTO05 | C254: AUTO IMPERF
A255: 509670 | B255: AUTO06 | C255: AutoID Polska S.A.
A256: 506361 | B256: AUTO07 | C256: "P.U.H. ""AUTO NAPRAWA"""
A257: 507320 | B257: AUTO08 | C257: AUTOS PW Sp. z o.o.
A258: 506691 | B258: AUTO09 | C258: Automatyka Przemysłowa
A259: 505744 | B259: AUTO10 | C259: Automatyka-Pomiary-Sterowanie S.A.
A260: 507009 | B260: AUTO11 | C260: AUTO NON-STOP
... A1416: 505376 | B1416: JANT01 | C1416: JANTER - Robert Szutkowski
A1417: 504472 | B1417: 36892 | C1417: ZAKŁAD ELEKTRYCZNY Zbigniew Janukie
A1418: 504665 | B1418: 37257 | C1418: Restauracja&Pub JANUS
A1419: 511917 | B1419: 37622 | C1419: JANUSZEWSKI TRANSPORT
A1420: 506580 | B1420: JAPA01 | C1420: JAPASZ Transport Handel Jan Ciman
A1421: 508792 | B1421: JAR 01 | C1421: P.P.H. JAR Sp. z o.o.
A1422: 504370 | B1422: JARM01 | C1422: Przedsiębiorstwo Handlowo Usługowo
A1423: 507264 | B1423: JARO01 | C1423: JAROTRANS Jarosław Kunda
A1424: 511358 | B1424: JARO02 | C1424: Jarosław Modrzyńaki
A1425: 507530 | B1425: JASF01 | C1425: JAS-FBG SA
A1426: 504445 | B1426: JASI01 | C1426: Usługi Transportowe Krzysztof Jasiń
A1427: 504721 | B1427: JASS01 | C1427: Jassmin PHU
...

Sheet Tabelle2
B1: BW: Belegnummer | C1: BW: BelPosit. | D1: D-Preis m² | E1: D-Preis kg | F1: Ist-Menge WE | G1: WE-Wert z. BUDAT KW
A2: =CONCATENATE(B2,C2) -> 450008745020 | B2: 4500087450 | C2: 20 | D2: 0.5710612 | E2: 8.1580172 | F2: 37957 | G2: 5062.54 | H2: 0.13337566 | I2: =+D2/H2 -> 4.2815998 | J2: =+E2/I2 -> 1.9053666
A3: =CONCATENATE(B3,C3) -> 450009039530 | B3: 4500090395 | C3: 30 | D3: 0.67453791 | E3: 9.6362559 | F3: 49428 | G3: 7749.77 | H3: 0.15678907 | I3: =+D3/H3 -> 4.3021999 | J3: =+E3/I3 -> 2.2398438
A4: =CONCATENATE(B4,C4) -> 450009228820 | B4: 4500092288 | C4: 20 | D4: 0.64133228 | E4: 8.5510971 | F4: 19613 | G4: 2936.63 | H4: 0.14972875 | I4: =+D4/H4 -> 4.2832941 | J4: =+E4/I4 -> 1.9963834
A5: =CONCATENATE(B5,C5) -> 450009330710 | B5: 4500093307 | C5: 10 | D5: 0.45339418 | E5: 9.0678836 | F5: 167640 | G5: 17525.25 | H5: 0.10454098 | I5: =+D5/H5 -> 4.3369995 | J5: =+E5/I5 -> 2.0908196
A6: =CONCATENATE(B6,C6) -> 450009410920 | B6: 4500094109 | C6: 20 | D6: 0.63853109 | E6: 8.5137478 | F6: 17387 | G6: 2607.12 | H6: 0.14994651 | I6: =+D6/H6 -> 4.2583924 | J6: =+E6/I6 -> 1.9992868
A7: =CONCATENATE(B7,C7) -> 450009586410 | B7: 4500095864 | C7: 10 | D7: 0.54913604 | E7: 9.1522673 | F7: 19700 | G7: 2540.15 | H7: 0.12894162 | I7: =+D7/H7 -> 4.2587957 | J7: =+E7/I7 -> 2.1490271
A8: =CONCATENATE(B8,C8) -> 450009604220 | B8: 4500096042 | C8: 20 | D8: 0.64558652 | E8: 9.2226646 | F8: 49657 | G8: 7503.13 | H8: 0.15109914 | I8: =+D8/H8 -> 4.2726022 | J8: =+E8/I8 -> 2.1585591
A9: =CONCATENATE(B9,C9) -> 450009605630 | B9: 4500096056 | C9: 30 | D9: 0.57610077 | E9: 8.230011 | F9: 252373 | G9: 33683.51 | H9: 0.13346717 | I9: =+D9/H9 -> 4.3164231 | J9: =+E9/I9 -> 1.9066739
A10: =CONCATENATE(B10,C10) -> 450009605650 | B10: 4500096056 | C10: 50 | D10: 0.58453912 | E10: 8.3505589 | F10: 37743 | G10: 5099.92 | H10: 0.13512227 | I10: =+D10/H10 -> 4.3260012 | J10: =+E10/I10 -> 1.9303182
A11: =CONCATENATE(B11,C11) -> 450009606130 | B11: 4500096061 | C11: 30 | D11: X | E11: X | F11: 0 | G11: 0 | H11: #DIV/0! | I11: =+D11/H11 -> #VALUE! | J11: =+E11/I11 -> #VALUE!
A12: =CONCATENATE(B12,C12) -> 450009606140 | B12: 4500096061 | C12: 40 | D12: 0.6385309 | E12: 8.5137453 | F12: 33694 | G12: 5052.29 | H12: 0.14994628 | I12: =+D12/H12 -> 4.2583977 | J12: =+E12/I12 -> 1.9992837
A13: =CONCATENATE(B13,C13) -> 450009606160 | B13: 4500096061 | C13: 60 | D13: 0.63761699 | E13: 8.5015599 | F13: 100667 | G13: 15097.49 | H13: 0.14997457 | I13: =+D13/H13 -> 4.2515007 | J13: =+E13/I13 -> 1.9996609
A14: =CONCATENATE(B14,C14) -> 450009606170 | B14: 4500096061 | C14: 70 | D14: 0.65006596 | E14: 8.6675461 | F14: 13493 | G14: 2021.33 | H14: 0.14980583 | I14: =+D14/H14 -> 4.3393904 | J14: =+E14/I14 -> 1.997411
A15: =CONCATENATE(B15,C15) -> 450009948920 | B15: 4500099489 | C15: 20 | D15: 0.65123406 | E15: 8.6831208 | F15: 238117 | G15: 35784.41 | H15: 0.15028079 | I15: =+D15/H15 -> 4.3334486 | J15: =+E15/I15 -> 2.0037438
A16: =CONCATENATE(B16,C16) -> 450009949170 | B16: 4500099491 | C16: 70 | D16: 0.56030819 | E16: 9.8299683 | F16: 65316 | G16: 8528.8 | H16: 0.1305775 | I16: =+D16/H16 -> 4.2910011 | J16: =+E16/I16 -> 2.2908333
A17: =CONCATENATE(B17,C17) -> 450009949540 | B17: 4500099495 | C17: 40 | D17: 0.65440587 | E17: 8.7254117 | F17: 85933 | G17: 13131.76 | H17: 0.15281394 | I17: =+D17/H17 -> 4.2823704 | J17: =+E17/I17 -> 2.0375192
A18: =CONCATENATE(B18,C18) -> 450009949550 | B18: 4500099495 | C18: 50 | D18: 0.66308387 | E18: 8.8411183 | F18: 12507 | G18: 1911.14 | H18: 0.15280563 | I18: =+D18/H18 -> 4.3393943 | J18: =+E18/I18 -> 2.0374084
A19: =CONCATENATE(B19,C19) -> 450009949560 | B19: 4500099495 | C19: 60 | D19: 0.66502472 | E19: 8.8669963 | F19: 170308 | G19: 25916.21 | H19: 0.15217259 | I19: =+D19/H19 -> 4.3702003 | J19: =+E19/I19 -> 2.0289679
A20: =CONCATENATE(B20,C20) -> 4500101019100 | B20: 4500101019 | C20: 100 | D20: 0.57379849 | E20: 8.1971213 | F20: 35572 | G20: 4698.16 | H20: 0.13207467 | I20: =+D20/H20 -> 4.3445008 | J20: =+E20/I20 -> 1.8867809
A21: =CONCATENATE(B21,C21) -> 450010104650 | B21: 4500101046 | C21: 50 | D21: 0.60447917 | E21: 8.6354167 | F21: 142772 | G21: 20264.56 | H21: 0.14193651 | I21: =+D21/H21 -> 4.2587996 | J21: =+E21/I21 -> 2.0276645
A22: =CONCATENATE(B22,C22) -> 450010305990 | B22: 4500103059 | C22: 90 | D22: 0.58391257 | E22: 8.3416081 | F22: 13771 | G22: 1872.19 | H22: 0.13595164 | I22: =+D22/H22 -> 4.2950021 | J22: =+E22/I22 -> 1.9421662
A23: =CONCATENATE(B23,C23) -> 450010471230 | B23: 4500104712 | C23: 30 | D23: 0.54322646 | E23: 8.3573301 | F23: 14815 | G23: 1867.44 | H23: 0.12605062 | I23: =+D23/H23 -> 4.3095896 | J23: =+E23/I23 -> 1.9392404
... A419: =CONCATENATE(B419,C419) -> 4500116134120 | B419: 4500116134 | C419: 120 | D419: 0.66064512 | E419: 9.4377878 | F419: 3632.843 | G419: 571.8 | H419: 0.15739739 | I419: =+D419/H419 -> 4.1973068 | J419: =+E419/I419 -> 2.2485342
A420: =CONCATENATE(B420,C420) -> 4500116134130 | B420: 4500116134 | C420: 130 | D420: X | E420: X | F420: 0 | G420: -0.71 | H420: #DIV/0! | I420: =+D420/H420 -> #VALUE! | J420: =+E420/I420 -> #VALUE!
A421: =CONCATENATE(B421,C421) -> 4500116134140 | B421: 4500116134 | C421: 140 | D421: 0.77410796 | E421: 9.6763495 | F421: 25750 | G421: 4636.4 | H421: 0.18005437 | I421: =+D421/H421 -> 4.2993012 | J421: =+E421/I421 -> 2.2506796
A422: =CONCATENATE(B422,C422) -> 450011614510 | B422: 4500116145 | C422: 10 | D422: 0.61927476 | E422: 10.321246 | F422: 82483 | G422: 11878.43 | H422: 0.14401064 | I422: =+D422/H422 -> 4.3002013 | J422: =+E422/I422 -> 2.4001774
A423: =CONCATENATE(B423,C423) -> 450011614520 | B423: 4500116145 | C423: 20 | D423: 0.77505188 | E423: 9.6881485 | F423: 28526 | G423: 5141.42 | H423: 0.18023628 | I423: =+D423/H423 -> 4.3001992 | J423: =+E423/I423 -> 2.2529534
A424: =CONCATENATE(B424,C424) -> 450011620110 | B424: 4500116201 | C424: 10 | D424: 0.61555125 | E424: 10.259188 | F424: 198049 | G424: 28488.57 | H424: 0.14384607 | I424: =+D424/H424 -> 4.2792358 | J424: =+E424/I424 -> 2.3974345
A425: =CONCATENATE(B425,C425) -> 450011620120 | B425: 4500116201 | C425: 20 | D425: 0.618829 | E425: 10.313817 | F425: 49633 | G425: 7134.74 | H425: 0.14374992 | I425: =+D425/H425 -> 4.3048997 | J425: =+E425/I425 -> 2.3958321
A426: =CONCATENATE(B426,C426) -> 450011622210 | B426: 4500116222 | C426: 10 | D426: 0.69410957 | E426: 8.6763696 | F426: 53300 | G426: 8515.6 | H426: 0.15976735 | I426: =+D426/H426 -> 4.3445019 | J426: =+E426/I426 -> 1.9970919
A427: =CONCATENATE(B427,C427) -> 450011624610 | B427: 4500116246 | C427: 10 | D427: 0.6276173 | E427: 10.460288 | F427: 710850 | G427: 102923.1 | H427: 0.14478877 | I427: =+D427/H427 -> 4.3347097 | J427: =+E427/I427 -> 2.4131462
A428: =CONCATENATE(B428,C428) -> 450011624710 | B428: 4500116247 | C428: 10 | D428: 0.55270919 | E428: 9.2118199 | F428: 850666 | G428: 109795.7 | H428: 0.12907028 | I428: =+D428/H428 -> 4.2822344 | J428: =+E428/I428 -> 2.1511714
A429: =CONCATENATE(B429,C429) -> 450011624720 | B429: 4500116247 | C429: 20 | D429: 0.5542191 | E429: 9.236985 | F429: 853296 | G429: 110211.36 | H429: 0.12915959 | I429: =+D429/H429 -> 4.2909637 | J429: =+E429/I429 -> 2.1526598
A430: =CONCATENATE(B430,C430) -> 450011624730 | B430: 4500116247 | C430: 30 | D430: 0.55367624 | E430: 9.2279373 | F430: 175949 | G430: 22702.48 | H430: 0.12902875 | I430: =+D430/H430 -> 4.2911074 | J430: =+E430/I430 -> 2.1504792
A431: =CONCATENATE(B431,C431) -> 450011625410 | B431: 4500116254 | C431: 10 | D431: 0.55923399 | E431: 8.6035998 | F431: 176368 | G431: 22928.91 | H431: 0.13000607 | I431: =+D431/H431 -> 4.3015992 | J431: =+E431/I431 -> 2.0000933
A432: =CONCATENATE(B432,C432) -> 450011628310 | B432: 4500116283 | C432: 10 | D432: 0.52298773 | E432: 9.1752234 | F432: 849540 | G432: 101590.71 | H432: 0.1195832 | I432: =+D432/H432 -> 4.3734215 | J432: =+E432/I432 -> 2.0979508
... A1231: =CONCATENATE(B1231,C1231) -> 450012480120 | B1231: 4500124801 | C1231: 20 | D1231: 0.55096789 | E1231: 7.8709698 | F1231: 50357 | G1231: 6489.62 | H1231: 0.12887225 | I1231: =+D1231/H1231 -> 4.2753027 | J1231: =+E1231/I1231 -> 1.8410322
A1232: =CONCATENATE(B1232,C1232) -> 450012491510 | B1232: 4500124915 | C1232: 10 | D1232: X | E1232: X | F1232: 0 | G1232: 24.36 | H1232: #DIV/0! | I1232: =+D1232/H1232 -> #VALUE! | J1232: =+E1232/I1232 -> #VALUE!
A1233: =CONCATENATE(B1233,C1233) -> 450012491520 | B1233: 4500124915 | C1233: 20 | D1233: 0.46477626 | E1233: 8.4504775 | F1233: 54036 | G1233: 5815.6 | H1233: 0.10762455 | I1233: =+D1233/H1233 -> 4.3184968 | J1233: =+E1233/I1233 -> 1.9568099
...
